Workbook

Sheet DataExp1.1
B1: Ag-aSi (bcsstk02)
B2: N=1 | G2: N=3 | L2: N = 5 | Q2: N = 10 | V2: N = 20 | AA2: N=50 | AF2: N = 100
B3: L-2 Norm Error | C3: L-infty Norm Error | D3: Acc. Write Latency (Mean) | E3: Acc. Write Energy (Mean) | F3: Elapsed Time for VMM | G3: L-2 Norm Error | H3: L-infty Norm Error | I3: Acc. Write Latency (Mean) | J3: Acc. Write Energy (Mean) | K3: Elapsed Time for VMM | L3: L-2 Norm Error | M3: L-infty Norm Error | N3: Acc. Write Latency (Mean) | O3: Acc. Write Energy (Mean) | P3: Elapsed Time for VMM | Q3: L-2 Norm Error | R3: L-infty Norm Error | S3: Acc. Write Latency (Mean) | T3: Acc. Write Energy (Mean) | U3: Elapsed Time for VMM | V3: L-2 Norm Error | W3: L-infty Norm Error | X3: Acc. Write Latency (Mean) | Y3: Acc. Write Energy (Mean) | Z3: Elapsed Time for VMM | AA3: L-2 Norm Error | AB3: L-infty Norm Error | AC3: Acc. Write Latency (Mean) | AD3: Acc. Write Energy (Mean) | AE3: Elapsed Time for VMM | AF3: L-2 Norm Error | AG3: L-infty Norm Error | AH3: Acc. Write Latency (Mean) | AI3: Acc. Write Energy (Mean) | AJ3: Elapsed Time for VMM
B4: 48.405376 | C4: 6.5012371 | D4: 280.77705 | E4: 0.0012426647 | F4: 2.2200265 | G4: 21.845976 | H4: 3.1394863 | I4: 390.73336 | J4: 0.0018323394 | K4: 2.094007 | L4: 11.761522 | M4: 1.9688228 | N4: 429.57062 | O4: 0.0020074487 | P4: 2.2919953 | Q4: 1.3352137 | R4: 0.40685535 | S4: 445.81593 | T4: 0.0020439141 | U4: 2.4829381 | V4: 1.1829449 | W4: 0.399075 | X4: 455.82186 | Y4: 0.0020637462 | Z4: 2.5318367 | AA4: 1.2670241 | AB4: 0.36013391 | AC4: 460.27455 | AD4: 0.002091303 | AE4: 3.1150029 | AF4: 1.1673841 | AG4: 0.35890659 | AH4: 458.09595 | AI4: 0.002114661 | AJ4: 4.3998079
B5: 48.544183 | C5: 6.6108192 | D5: 280.77705 | E5: 0.001242368 | F5: 2.3025551 | G5: 22.109666 | H5: 3.4227544 | I5: 391.11196 | J5: 0.0018332876 | K5: 2.1610165 | L5: 11.893732 | M5: 2.1001162 | N5: 429.74972 | O5: 0.0020082558 | P5: 1.9957106 | Q5: 2.2105762 | R5: 0.578478 | S5: 456.20403 | T5: 0.0020599181 | U5: 2.360991 | V5: 1.1341129 | W5: 0.38645739 | X5: 445.07466 | Y5: 0.0020497697 | Z5: 2.5911741 | AA5: 1.942108 | AB5: 0.51635459 | AC5: 449.30295 | AD5: 0.0020859872 | AE5: 3.1055176 | AF5: 1.0903015 | AG5: 0.37369292 | AH5: 453.036 | AI5: 0.0020849599 | AJ5: 4.2901444
B6: 49.038547 | C6: 6.7529914 | D6: 280.77705 | E6: 0.0012444119 | F6: 2.21224 | G6: 22.153908 | H6: 3.3333766 | I6: 393.00406 | J6: 0.0018425507 | K6: 1.9767847 | L6: 12.028675 | M6: 1.9953561 | N6: 428.94287 | O6: 0.0020055729 | P6: 2.4549811 | Q6: 1.8859265 | R6: 0.57416553 | S6: 452.44893 | T6: 0.0020656273 | U6: 2.2117264 | V6: 1.179341 | W6: 0.33143759 | X6: 456.26781 | Y6: 0.0020669548 | Z6: 2.461961 | AA6: 2.2144552 | AB6: 0.58196221 | AC6: 459.0537 | AD6: 0.0020826491 | AE6: 2.9935327 | AF6: 1.180713 | AG6: 0.3654624 | AH6: 451.87185 | AI6: 0.0020796577 | AJ6: 3.9376497
B7: 43.487215 | C7: 6.2384247 | D7: 280.77705 | E7: 0.0012417746 | F7: 1.8635902 | G7: 21.261906 | H7: 3.0833856 | I7: 390.03646 | J7: 0.0018291589 | K7: 2.242346 | L7: 12.05252 | M7: 1.988057 | N7: 429.54932 | O7: 0.0020109966 | P7: 2.4079876 | Q7: 1.3848403 | R7: 0.41059123 | S7: 446.15463 | T7: 0.0020458236 | U7: 2.1957183 | V7: 1.1135811 | W7: 0.33484981 | X7: 463.96941 | Y7: 0.0020674293 | Z7: 2.726192 | AA7: 1.9260217 | AB7: 0.52223126 | AC7: 445.0116 | AD7: 0.0020738131 | AE7: 3.0592046 | AF7: 1.1272065 | AG7: 0.39454568 | AH7: 452.2389 | AI7: 0.0020824642 | AJ7: 3.894516
B8: 48.887283 | C8: 6.7488675 | D8: 280.77705 | E8: 0.0012414779 | F8: 2.1537321 | G8: 21.911303 | H8: 3.1442256 | I8: 390.73336 | J8: 0.0018323266 | K8: 2.4188924 | L8: 12.212792 | M8: 2.0223212 | N8: 429.57062 | O8: 0.0020074787 | P8: 2.4520345 | Q8: 1.1210565 | R8: 0.38142931 | S8: 441.88533 | T8: 0.0020443423 | U8: 2.1223922 | V8: 1.2980959 | W8: 0.37077354 | X8: 464.41806 | Y8: 0.0020691606 | Z8: 2.4865382 | AA8: 1.1100289 | AB8: 0.37213682 | AC8: 451.0578 | AD8: 0.0020726877 | AE8: 2.8059626 | AF8: 1.2381096 | AG8: 0.34792244 | AH8: 464.89035 | AI8: 0.0021306027 | AJ8: 3.9945855
B10: AlOx-HfO2 (bcsstk02)
B11: N=1 | G11: N=3 | L11: N = 5 | Q11: N = 10 | V11: N = 20 | AA11: N=50 | AF11: N = 100
B12: L-2 Norm Error | C12: L-infty Norm Error | D12: Acc. Write Latency (Mean) | E12: Acc. Write Energy (Mean) | F12: Elapsed Time for VMM | G12: L-2 Norm Error | H12: L-infty Norm Error | I12: Acc. Write Latency (Mean) | J12: Acc. Write Energy (Mean) | K12: Elapsed Time for VMM | L12: L-2 Norm Error | M12: L-infty Norm Error | N12: Acc. Write Latency (Mean) | O12: Acc. Write Energy (Mean) | P12: Elapsed Time for VMM | Q12: L-2 Norm Error | R12: L-infty Norm Error | S12: Acc. Write Latency (Mean) | T12: Acc. Write Energy (Mean) | U12: Elapsed Time for VMM | V12: L-2 Norm Error | W12: L-infty Norm Error | X12: Acc. Write Latency (Mean) | Y12: Acc. Write Energy (Mean) | Z12: Elapsed Time for VMM | AA12: L-2 Norm Error | AB12: L-infty Norm Error | AC12: Acc. Write Latency (Mean) | AD12: Acc. Write Energy (Mean) | AE12: Elapsed Time for VMM | AF12: L-2 Norm Error | AG12: L-infty Norm Error | AH12: Acc. Write Latency (Mean) | AI12: Acc. Write Energy (Mean) | AJ12: Elapsed Time for VMM
B13: 97.996821 | C13: 12.857807 | D13: 38.801853 | E13: 0.018313175 | F13: 2.0837293 | G13: 1.9896208 | H13: 0.50061643 | I13: 73.284409 | J13: 0.038994967 | K13: 2.2478783 | L13: 4.5773183 | M13: 0.91697727 | N13: 75.286565 | O13: 0.04025648 | P13: 2.1818914 | Q13: 4.7144056 | R13: 0.93996264 | S13: 75.54508 | T13: 0.040608117 | U13: 2.4497466 | V13: 4.8169352 | W13: 1.0320496 | X13: 75.60866 | Y13: 0.040527248 | Z13: 2.5657914 | AA13: 2.7078721 | AB13: 0.71523257 | AC13: 75.365401 | AD13: 0.040554784 | AE13: 3.1021006 | AF13: 6.6956419 | AG13: 1.3544097 | AH13: 77.501151 | AI13: 0.042091459 | AJ13: 4.2037108
B14: 94.688351 | C14: 12.770238 | D14: 38.801853 | E14: 0.018313175 | F14: 2.0653238 | G14: 5.6400916 | H14: 0.96441459 | I14: 71.477009 | J14: 0.037265886 | K14: 2.2695355 | L14: 5.219326 | M14: 1.0107985 | N14: 75.602615 | O14: 0.040260067 | P14: 2.0102851 | Q14: 6.4349289 | R14: 1.3347418 | S14: 77.55073 | T14: 0.04215238 | U14: 2.4255056 | V14: 4.6786405 | W14: 0.94171617 | X14: 75.51851 | Y14: 0.040606052 | Z14: 2.6950169 | AA14: 4.6470075 | AB14: 0.94297207 | AC14: 75.518601 | AD14: 0.040606176 | AE14: 3.0403452 | AF14: 2.847067 | AG14: 0.76356066 | AH14: 75.219351 | AI14: 0.040552803 | AJ14: 4.0056276
B15: 100.73985 | C15: 13.653299 | D15: 38.801853 | E15: 0.018313175 | F15: 1.8172278 | G15: 4.3719318 | H15: 0.88990458 | I15: 73.102359 | J15: 0.038879755 | K15: 2.3029404 | L15: 6.4286581 | M15: 1.257624 | N15: 76.178365 | O15: 0.041812025 | P15: 2.0426908 | Q15: 6.7298768 | R15: 1.3547178 | S15: 77.50088 | T15: 0.042090952 | U15: 2.3199012 | V15: 2.6889885 | W15: 0.63557735 | X15: 75.21911 | Y15: 0.040551775 | Z15: 2.6627848 | AA15: 2.4164368 | AB15: 0.66913715 | AC15: 75.421251 | AD15: 0.040647352 | AE15: 3.2617388 | AF15: 2.3307099 | AG15: 0.49352867 | AH15: 75.588301 | AI15: 0.040547277 | AJ15: 4.0872819
B16: 100.37812 | C16: 13.654371 | D16: 38.801853 | E16: 0.018313175 | F16: 2.010648 | G16: 1.9210445 | H16: 0.47525592 | I16: 73.280859 | J16: 0.039008239 | K16: 2.3186951 | L16: 4.8547848 | M16: 0.90377899 | N16: 75.110315 | O16: 0.040272301 | P16: 2.2661731 | Q16: 2.7311094 | R16: 0.71522455 | S16: 75.36528 | T16: 0.040554723 | U16: 2.0072596 | V16: 6.7932464 | W16: 1.2931129 | X16: 76.69296 | Y16: 0.042155794 | Z16: 2.5493519 | AA16: 2.7785448 | AB16: 0.76410568 | AC16: 75.219201 | AD16: 0.040552263 | AE16: 3.174298 | AF16: 3.3416006 | AG16: 0.83163335 | AH16: 75.272551 | AI16: 0.040573162 | AJ16: 3.998477
B17: 98.816185 | C17: 12.904267 | D17: 38.801853 | E17: 0.018313175 | F17: 2.1616821 | G17: 4.0246053 | H17: 0.80545388 | I17: 73.238509 | J17: 0.038928413 | K17: 2.3394191 | L17: 2.3629086 | M17: 0.6481086 | N17: 74.950415 | O17: 0.040250394 | P17: 2.3130269 | Q17: 2.6611317 | R17: 0.63677796 | S17: 75.21908 | T17: 0.04055157 | U17: 2.3707435 | V17: 4.7132427 | W17: 0.9439278 | X17: 75.54511 | Y17: 0.04060827 | Z17: 2.640862 | AA17: 4.9572738 | AB17: 1.0182821 | AC17: 75.715151 | AD17: 0.040532795 | AE17: 3.08707 | AF17: 5.0719053 | AG17: 1.0501216 | AH17: 76.011051 | AI17: 0.040587721 | AJ17: 4.2727709
B19: EpiRAM (bcsstk02)
B20: N=1 | G20: N=3 | L20: N = 5 | Q20: N = 10 | V20: N = 20 | AA20: N=50 | AF20: N = 100
B21: L-2 Norm Error | C21: L-infty Norm Error | D21: Acc. Write Latency (Mean) | E21: Acc. Write Energy (Mean) | F21: Elapsed Time for VMM | G21: L-2 Norm Error | H21: L-infty Norm Error | I21: Acc. Write Latency (Mean) | J21: Acc. Write Energy (Mean) | K21: Elapsed Time for VMM | L21: L-2 Norm Error | M21: L-infty Norm Error | N21: Acc. Write Latency (Mean) | O21: Acc. Write Energy (Mean) | P21: Elapsed Time for VMM | Q21: L-2 Norm Error | R21: L-infty Norm Error | S21: Acc. Write Latency (Mean) | T21: Acc. Write Energy (Mean) | U21: Elapsed Time for VMM | V21: L-2 Norm Error | W21: L-infty Norm Error | X21: Acc. Write Latency (Mean) | Y21: Acc. Write Energy (Mean) | Z21: Elapsed Time for VMM | AA21: L-2 Norm Error | AB21: L-infty Norm Error | AC21: Acc. Write Latency (Mean) | AD21: Acc. Write Energy (Mean) | AE21: Elapsed Time for VMM | AF21: L-2 Norm Error | AG21: L-infty Norm Error | AH21: Acc. Write Latency (Mean) | AI21: Acc. Write Energy (Mean) | AJ21: Elapsed Time for VMM
B22: 4.5673915 | C22: 0.75511641 | D22: 0.044845013 | E22: 0.00013224449 | F22: 0.21188092 | G22: 5.2461342 | H22: 0.87969942 | I22: 0.047820026 | J22: 0.00013390877 | K22: 0.24222088 | L22: 5.0655325 | M22: 0.85534651 | N22: 0.047842539 | O22: 0.00013391573 | P22: 0.24848962 | Q22: 4.8376725 | R22: 0.78702981 | S22: 0.047835071 | T22: 0.00013392119 | U22: 0.38945293 | V22: 5.0660258 | W22: 0.85534651 | X22: 0.047852636 | Y22: 0.00013391596 | Z22: 0.33267808 | AA22: 4.8659136 | AB22: 0.80604507 | AC22: 0.047865331 | AD22: 0.00013392157 | AE22: 0.54658175 | AF22: 5.2482588 | AG22: 0.87969942 | AH22: 0.047843155 | AI22: 0.00013391634 | AJ22: 0.83352232
B23: 4.5033926 | C23: 0.75511641 | D23: 0.044845013 | E23: 0.00013223692 | F23: 0.21985817 | G23: 4.8659136 | H23: 0.80604507 | I23: 0.047850026 | J23: 0.00013391539 | K23: 0.22238779 | L23: 5.4064632 | M23: 0.87969942 | N23: 0.047932539 | O23: 0.00013393567 | P23: 0.2499547 | Q23: 5.1555632 | R23: 0.87969942 | S23: 0.047857571 | T23: 0.0001339174 | U23: 0.27711892 | V23: 5.1555632 | W23: 0.87969942 | X23: 0.047857636 | Y23: 0.00013391758 | Z23: 0.3296144 | AA23: 5.0660258 | AB23: 0.85534651 | AC23: 0.047852831 | AD23: 0.00013391651 | AE23: 0.50734711 | AF23: 5.1122342 | AG23: 0.85534651 | AH23: 0.047853155 | AI23: 0.00013391607 | AJ23: 0.81701493
B24: 4.5673915 | C24: 0.75511641 | D24: 0.044845013 | E24: 0.00013222936 | F24: 0.20500302 | G24: 4.851945 | H24: 0.80579231 | I24: 0.047850026 | J24: 0.00013391514 | K24: 0.22048783 | L24: 4.8532426 | M24: 0.80579231 | N24: 0.047847539 | O24: 0.00013391723 | P24: 0.22810745 | Q24: 5.2813135 | R24: 0.87969942 | S24: 0.047885071 | T24: 0.00013392425 | U24: 0.27209091 | V24: 4.8865086 | W24: 0.80604507 | X24: 0.047842636 | Y24: 0.00013391892 | Z24: 0.29948545 | AA24: 5.1394444 | AB24: 0.85534651 | AC24: 0.047840331 | AD24: 0.00013391785 | AE24: 0.56244802 | AF24: 4.8546455 | AG24: 0.80604507 | AH24: 0.047835655 | AI24: 0.00013391792 | AJ24: 0.85503769
B25: 4.5673915 | C25: 0.75511641 | D25: 0.044845013 | E25: 0.0001322218 | F25: 0.21112823 | G25: 4.8845713 | H25: 0.80604507 | I25: 0.047832526 | J25: 0.00013391756 | K25: 0.22298312 | L25: 5.2461342 | M25: 0.87969942 | N25: 0.047840039 | O25: 0.00013391599 | P25: 0.26530623 | Q25: 5.1901347 | R25: 0.87969942 | S25: 0.047860071 | T25: 0.0001339167 | U25: 0.25890827 | V25: 5.286176 | W25: 0.87969942 | X25: 0.047867636 | Y25: 0.000133915 | Z25: 0.31969666 | AA25: 5.3216704 | AB25: 0.87969942 | AC25: 0.047905331 | AD25: 0.00013392644 | AE25: 0.50159717 | AF25: 5.2681976 | AG25: 0.87969942 | AH25: 0.047868155 | AI25: 0.00013392154 | AJ25: 0.83273315
B26: 4.520132 | C26: 0.75511641 | D26: 0.044845013 | E26: 0.00013221424 | F26: 0.24598479 | G26: 5.1555632 | H26: 0.87969942 | I26: 0.047847526 | J26: 0.00013391369 | K26: 0.23683763 | L26: 5.1889067 | M26: 0.87969942 | N26: 0.047850039 | O26: 0.0001339167 | P26: 0.23890328 | Q26: 4.8546763 | R26: 0.80604507 | S26: 0.047842571 | T26: 0.0001339237 | U26: 0.24119282 | V26: 5.0655325 | W26: 0.85534651 | X26: 0.047842636 | Y26: 0.00013391595 | Z26: 0.28762221 | AA26: 5.2813135 | AB26: 0.87969942 | AC26: 0.047847831 | AD26: 0.00013391622 | AE26: 0.53132796 | AF26: 5.0227221 | AG26: 0.85534651 | AH26: 0.047843155 | AI26: 0.0001339199 | AJ26: 0.86136317
B28: TaOx-HfOx (bcsstk02)
B29: N=1 | G29: N=3 | L29: N = 5 | Q29: N = 10 | V29: N = 20 | AA29: N=50 | AF29: N = 100
B30: L-2 Norm Error | C30: L-infty Norm Error | D30: Acc. Write Latency (Mean) | E30: Acc. Write Energy (Mean) | F30: Elapsed Time for VMM | G30: L-2 Norm Error | H30: L-infty Norm Error | I30: Acc. Write Latency (Mean) | J30: Acc. Write Energy (Mean) | K30: Elapsed Time for VMM | L30: L-2 Norm Error | M30: L-infty Norm Error | N30: Acc. Write Latency (Mean) | O30: Acc. Write Energy (Mean) | P30: Elapsed Time for VMM | Q30: L-2 Norm Error | R30: L-infty Norm Error | S30: Acc. Write Latency (Mean) | T30: Acc. Write Energy (Mean) | U30: Elapsed Time for VMM | V30: L-2 Norm Error | W30: L-infty Norm Error | X30: Acc. Write Latency (Mean) | Y30: Acc. Write Energy (Mean) | Z30: Elapsed Time for VMM | AA30: L-2 Norm Error | AB30: L-infty Norm Error | AC30: Acc. Write Latency (Mean) | AD30: Acc. Write Energy (Mean) | AE30: Elapsed Time for VMM | AF30: L-2 Norm Error | AG30: L-infty Norm Error | AH30: Acc. Write Latency (Mean) | AI30: Acc. Write Energy (Mean) | AJ30: Elapsed Time for VMM
B31: 69.401946 | C31: 9.0642809 | D31: 0.062164239 | E31: 1.8113524e-05 | F31: 2.1059375 | G31: 3.9215875 | H31: 0.70745043 | I31: 0.088056366 | J31: 2.7909643e-05 | K31: 2.2464616 | L31: 3.8183915 | M31: 0.69895933 | N31: 0.088401044 | O31: 2.8035839e-05 | P31: 2.4535985 | Q31: 3.9247302 | R31: 0.73391998 | S31: 0.088616788 | T31: 2.8175268e-05 | U31: 2.3361292 | V31: 3.8181739 | W31: 0.69893564 | X31: 0.088446251 | Y31: 2.8157872e-05 | Z31: 2.6465549 | AA31: 3.9278824 | AB31: 0.72442487 | AC31: 0.088203191 | AD31: 2.8303537e-05 | AE31: 3.0650082 | AF31: 3.8354882 | AG31: 0.70595755 | AH31: 0.088415207 | AI31: 2.8776972e-05 | AJ31: 3.9523067
B32: 68.916185 | C32: 9.1648874 | D32: 0.062164239 | E32: 1.8086741e-05 | F32: 1.8504958 | G32: 3.9215757 | H32: 0.70745833 | I32: 0.088056366 | J32: 2.7916576e-05 | K32: 2.1323521 | L32: 3.8887265 | M32: 0.72133648 | N32: 0.088540344 | O32: 2.8099164e-05 | P32: 2.0277879 | Q32: 3.7591791 | R32: 0.69152667 | S32: 0.088391188 | T32: 2.807857e-05 | U32: 2.4931118 | V32: 3.8006592 | W32: 0.69891181 | X32: 0.088456201 | Y32: 2.8169647e-05 | Z32: 2.2847562 | AA32: 3.7585107 | AB32: 0.69152667 | AC32: 0.088511741 | AD32: 2.8413532e-05 | AE32: 3.0348001 | AF32: 3.9270207 | AG32: 0.72441697 | AH32: 0.088353882 | AI32: 2.8740707e-05 | AJ32: 4.0790761
B33: 68.964609 | C33: 9.160322 | D33: 0.062164239 | E33: 1.8099707e-05 | F33: 2.0990152 | G33: 3.749366 | H33: 0.68316181 | I33: 0.088273741 | J33: 2.7994616e-05 | K33: 2.2492113 | L33: 3.7045607 | M33: 0.68309849 | N33: 0.088307994 | O33: 2.8014527e-05 | P33: 2.1771913 | Q33: 3.7296431 | R33: 0.69921988 | S33: 0.088323063 | T33: 2.8058825e-05 | U33: 2.1479766 | V33: 3.9457578 | W33: 0.71548446 | X33: 0.088446251 | Y33: 2.8164524e-05 | Z33: 2.5861542 | AA33: 3.7297592 | AB33: 0.69921988 | AC33: 0.088443616 | AD33: 2.8409426e-05 | AE33: 3.1067278 | AF33: 3.81843 | AG33: 0.69896723 | AH33: 0.088687357 | AI33: 2.8858937e-05 | AJ33: 4.2503848
B34: 69.172552 | C34: 9.1551007 | D34: 0.062164239 | E34: 1.8033175e-05 | F34: 1.9400661 | G34: 3.7228044 | H34: 0.69135268 | I34: 0.088273741 | J34: 2.8015435e-05 | K34: 2.1871917 | L34: 3.7230943 | M34: 0.70162901 | N34: 0.088254894 | O34: 2.800221e-05 | P34: 2.2983134 | Q34: 3.8354075 | R34: 0.70599705 | S34: 0.088143963 | T34: 2.7991991e-05 | U34: 2.5393827 | V34: 3.7290938 | W34: 0.69918828 | X34: 0.088353201 | Y34: 2.8151395e-05 | Z34: 2.5232589 | AA34: 3.7232682 | AB34: 0.7017159 | AC34: 0.088390516 | AD34: 2.8395146e-05 | AE34: 3.0574563 | AF34: 4.1305605 | AG34: 0.74397459 | AH34: 0.088718832 | AI34: 2.8889242e-05 | AJ34: 3.9828606
B35: 69.139875 | C35: 9.1556615 | D35: 0.062164239 | E35: 1.8006392e-05 | F35: 2.1525822 | G35: 3.7406837 | H35: 0.68639243 | I35: 0.088292016 | J35: 2.7991977e-05 | K35: 2.47803 | L35: 3.8355051 | M35: 0.70596545 | N35: 0.088128894 | O35: 2.7956684e-05 | P35: 2.2626951 | Q35: 3.8649254 | R35: 0.72606857 | S35: 0.088565363 | T35: 2.8148309e-05 | U35: 2.1721127 | V35: 3.8079109 | W35: 0.7088564 | X35: 0.088203801 | Y35: 2.8106798e-05 | Z35: 2.4819605 | AA35: 3.807864 | AB35: 0.7088564 | AC35: 0.088294216 | AD35: 2.8368369e-05 | AE35: 3.0213196 | AF35: 3.9283257 | AG35: 0.71459088 | AH35: 0.088391857 | AI35: 2.8784334e-05 | AJ35: 4.0355628
B38: Ag-aSi (Iperturb)
B39: N=1 | G39: N=3 | L39: N = 5 | Q39: N = 10 | V39: N = 20 | AA39: N=50 | AF39: N = 100
B40: L-2 Norm Error | C40: L-infty Norm Error | D40: Acc. Write Latency (Mean) | E40: Acc. Write Energy (Mean) | F40: Elapsed Time for VMM | G40: L-2 Norm Error | H40: L-infty Norm Error | I40: Acc. Write Latency (Mean) | J40: Acc. Write Energy (Mean) | K40: Elapsed Time for VMM | L40: L-2 Norm Error | M40: L-infty Norm Error | N40: Acc. Write Latency (Mean) | O40: Acc. Write Energy (Mean) | P40: Elapsed Time for VMM | Q40: L-2 Norm Error | R40: L-infty Norm Error | S40: Acc. Write Latency (Mean) | T40: Acc. Write Energy (Mean) | U40: Elapsed Time for VMM | V40: L-2 Norm Error | W40: L-infty Norm Error | X40: Acc. Write Latency (Mean) | Y40: Acc. Write Energy (Mean) | Z40: Elapsed Time for VMM | AA40: L-2 Norm Error | AB40: L-infty Norm Error | AC40: Acc. Write Latency (Mean) | AD40: Acc. Write Energy (Mean) | AE40: Elapsed Time for VMM | AF40: L-2 Norm Error | AG40: L-infty Norm Error | AH40: Acc. Write Latency (Mean) | AI40: Acc. Write Energy (Mean) | AJ40: Elapsed Time for VMM
B41: 51.534758 | C41: 7.5111976 | D41: 273.03645 | E41: 0.00083449493 | F41: 2.0030987 | G41: 28.70471 | H41: 4.3249273 | I41: 451.28821 | J41: 0.0016203724 | K41: 2.0151906 | L41: 13.316784 | M41: 2.7267831 | N41: 532.75202 | O41: 0.0019410649 | P41: 2.1397951 | Q41: 2.5283933 | R41: 1.1416819 | S41: 605.45928 | T41: 0.0022078399 | U41: 2.0364957 | V41: 1.2239236 | W41: 0.29159587 | X41: 583.81926 | Y41: 0.0021973805 | AA41: 2.5248051 | AB41: 1.1418794 | AC41: 600.56835 | AD41: 0.0022182442 | AF41: 2.4631756 | AG41: 0.65063953 | AH41: 593.4075 | AI41: 0.0022549485
B42: 47.441039 | C42: 6.8700695 | D42: 273.03645 | E42: 0.0008337682 | F42: 1.5547044 | G42: 29.424846 | H42: 4.3675534 | I42: 448.22836 | J42: 0.0016144407 | K42: 2.0086219 | L42: 15.023521 | M42: 2.6610517 | N42: 530.84567 | O42: 0.0019788305 | P42: 2.0948272 | Q42: 2.505464 | R42: 0.61801754 | S42: 580.63263 | T42: 0.0021944578 | U42: 2.1660569 | V42: 2.4730819 | W42: 0.64988916 | X42: 580.87116 | Y42: 0.0021965371 | AA42: 1.4170055 | AB42: 0.39626657 | AC42: 591.7653 | AD42: 0.0022475512 | AF42: 1.2150428 | AG42: 0.32048175 | AH42: 663.50445 | AI42: 0.0023719173
B43: 51.407432 | C43: 7.4953447 | D43: 273.03645 | E43: 0.00083304148 | F43: 2.0061657 | G43: 28.727845 | H43: 4.2807676 | I43: 451.13836 | J43: 0.0016208359 | K43: 1.9347098 | L43: 21.754593 | M43: 3.7011712 | N43: 536.84492 | O43: 0.0019934729 | P43: 1.8163373 | Q43: 1.9941022 | R43: 0.59871208 | S43: 640.72038 | T43: 0.0023330671 | U43: 2.2554374 | V43: 2.4666373 | W43: 0.6198501 | X43: 581.31186 | Y43: 0.0021855435 | AA43: 1.2222378 | AB43: 0.28641069 | AC43: 586.48185 | AD43: 0.0022254837 | AF43: 1.3735209 | AG43: 0.31335654 | AH43: 681.98295 | AI43: 0.002466285
B44: 47.441039 | C44: 6.8700695 | D44: 273.03645 | E44: 0.00083231475 | F44: 1.642509 | G44: 30.206496 | H44: 4.8971326 | I44: 448.92616 | J44: 0.0016157059 | K44: 1.9593127 | L44: 14.861652 | M44: 2.6977648 | N44: 532.19252 | O44: 0.0019751336 | P44: 1.7123663 | Q44: 3.7727422 | R44: 0.80488798 | S44: 645.81693 | T44: 0.0022039911 | U44: 1.7450409 | V44: 1.253476 | W44: 0.31612951 | X44: 586.48626 | Y44: 0.0022152288 | AA44: 1.7763398 | AB44: 0.43837675 | AC44: 686.7243 | AD44: 0.0022730587 | AF44: 1.2548157 | AG44: 0.31061625 | AH44: 590.53215 | AI44: 0.0022430086
B45: 47.7213 | C45: 6.9068462 | D45: 273.03645 | E45: 0.00083158803 | F45: 1.9367862 | G45: 29.704968 | H45: 4.4056157 | I45: 449.82256 | J45: 0.0016188457 | K45: 2.0695763 | L45: 13.360265 | M45: 2.6486962 | N45: 532.86017 | O45: 0.0019749131 | P45: 2.1647706 | Q45: 2.6151427 | R45: 1.1344625 | S45: 610.01763 | T45: 0.0022685998 | U45: 2.2797809 | V45: 2.4665934 | W45: 0.6185863 | X45: 581.17356 | Y45: 0.0021796156 | AA45: 1.2422573 | AB45: 0.2973586 | AC45: 590.08425 | AD45: 0.0022398103 | AF45: 2.226749 | AG45: 0.4609432 | AH45: 601.413 | AI45: 0.0022662424
...

Sheet Experiment 1.1
A1: Centralized Computation (Small-scale); Fixed Number of Iterations for Error Correction; Only applied Error Correction on Worst Device (a.k.a. excluding EpiRAM): Run 5 replications for each number of iterations
A3: Material | B3: No. iteration | C3: Matrix Name | D3: Matrix Row | E3: Matrix Column | F3: Conditioning Number | G3: MCA Rows | H3: MCA Columns | I3: Cell Rows | J3: Cell Columns | L3: L-2 Norm Error (Mean) | M3: L-infty Norm Error (Mean) | N3: Acc. Write Latency (Mean) | O3: Acc. Write Energy (Mean) | P3: Elapsed Time for VMM
A4: Ag-aSi | B4: 1 | C4: bcsstk02 | D4: 66 | E4: 66 | F4: 13000 | G4: 1 | H4: 1 | I4: 66 | J4: 66 | L4: =AVERAGE(DataExp1.1!B4:B8) -> 47.672521 | M4: =AVERAGE(DataExp1.1!C4:C8) -> 6.570468 | N4: =AVERAGE(DataExp1.1!D4:D8) -> 280.77705 | O4: =AVERAGE(DataExp1.1!E4:E8) -> 0.0012425394 | P4: =AVERAGE(DataExp1.1!F4:F8) -> 2.1504288
B5: 3 | L5: =AVERAGE(DataExp1.1!G4:G8) -> 21.856552 | M5: =AVERAGE(DataExp1.1!H4:H8) -> 3.2246457 | N5: =AVERAGE(DataExp1.1!I4:I8) -> 391.12384 | O5: =AVERAGE(DataExp1.1!J4:J8) -> 0.0018339326 | P5: =AVERAGE(DataExp1.1!K4:K8) -> 2.1786093
B6: 5 | L6: =AVERAGE(DataExp1.1!L4:L8) -> 11.989848 | M6: =AVERAGE(DataExp1.1!M4:M8) -> 2.0149347 | N6: =AVERAGE(DataExp1.1!N4:N8) -> 429.47663 | O6: =AVERAGE(DataExp1.1!O4:O8) -> 0.0020079505 | P6: =AVERAGE(DataExp1.1!P4:P8) -> 2.3205418
B7: 10 | L7: =AVERAGE(DataExp1.1!Q4:Q8) -> 1.5875226 | M7: =AVERAGE(DataExp1.1!R4:R8) -> 0.47030388 | N7: =AVERAGE(DataExp1.1!S4:S8) -> 448.50177 | O7: =AVERAGE(DataExp1.1!T4:T8) -> 0.0020519251 | P7: =AVERAGE(DataExp1.1!U4:U8) -> 2.2747532
B8: 20 | L8: =AVERAGE(DataExp1.1!V4:V8) -> 1.1816152 | M8: =AVERAGE(DataExp1.1!W4:W8) -> 0.36451866 | N8: =AVERAGE(DataExp1.1!X4:X8) -> 457.11036 | O8: =AVERAGE(DataExp1.1!Y4:Y8) -> 0.0020634121 | P8: =AVERAGE(DataExp1.1!Z4:Z8) -> 2.5595404
B9: 50 | L9: =AVERAGE(DataExp1.1!AA4:AA8) -> 1.6919276 | M9: =AVERAGE(DataExp1.1!AB4:AB8) -> 0.47056376 | N9: =AVERAGE(DataExp1.1!AC4:AC8) -> 452.94012 | O9: =AVERAGE(DataExp1.1!AD4:AD8) -> 0.002081288 | P9: =AVERAGE(DataExp1.1!AE4:AE8) -> 3.0158441
B10: 100 | L10: =AVERAGE(DataExp1.1!AF4:AF8) -> 1.1607429 | M10: =AVERAGE(DataExp1.1!AG4:AG8) -> 0.36810601 | N10: =AVERAGE(DataExp1.1!AH4:AH8) -> 456.02661 | O10: =AVERAGE(DataExp1.1!AI4:AI8) -> 0.0020984691 | P10: =AVERAGE(DataExp1.1!AJ4:AJ8) -> 4.1033407
A11: AlOx-HfO2 | B11: 1 | L11: =AVERAGE(DataExp1.1!B13:B17) -> 98.523865 | M11: =AVERAGE(DataExp1.1!C13:C17) -> 13.167996 | N11: =AVERAGE(DataExp1.1!D13:D17) -> 38.801853 | O11: =AVERAGE(DataExp1.1!E13:E17) -> 0.018313175 | P11: =AVERAGE(DataExp1.1!F13:F17) -> 2.0277222
B12: 3 | L12: =AVERAGE(DataExp1.1!G13:G17) -> 3.5894588 | M12: =AVERAGE(DataExp1.1!H13:H17) -> 0.72712908 | N12: =AVERAGE(DataExp1.1!I13:I17) -> 72.876629 | O12: =AVERAGE(DataExp1.1!J13:J17) -> 0.038615452 | P12: =AVERAGE(DataExp1.1!K13:K17) -> 2.2956937
B13: 5 | L13: =AVERAGE(DataExp1.1!L13:L17) -> 4.6885991 | M13: =AVERAGE(DataExp1.1!M13:M17) -> 0.94745747 | N13: =AVERAGE(DataExp1.1!N13:N17) -> 75.425655 | O13: =AVERAGE(DataExp1.1!O13:O17) -> 0.040570253 | P13: =AVERAGE(DataExp1.1!P13:P17) -> 2.1628135
B14: 10 | L14: =AVERAGE(DataExp1.1!Q13:Q17) -> 4.6542905 | M14: =AVERAGE(DataExp1.1!R13:R17) -> 0.99628494 | N14: =AVERAGE(DataExp1.1!S13:S17) -> 76.23621 | O14: =AVERAGE(DataExp1.1!T13:T17) -> 0.041191548 | P14: =AVERAGE(DataExp1.1!U13:U17) -> 2.3146313
B15: 20 | L15: =AVERAGE(DataExp1.1!V13:V17) -> 4.7382107 | M15: =AVERAGE(DataExp1.1!W13:W17) -> 0.96927676 | N15: =AVERAGE(DataExp1.1!X13:X17) -> 75.71687 | O15: =AVERAGE(DataExp1.1!Y13:Y17) -> 0.040889828 | P15: =AVERAGE(DataExp1.1!Z13:Z17) -> 2.6227614
B16: 50 | L16: =AVERAGE(DataExp1.1!AA13:AA17) -> 3.501427 | M16: =AVERAGE(DataExp1.1!AB13:AB17) -> 0.8219459 | N16: =AVERAGE(DataExp1.1!AC13:AC17) -> 75.447921 | O16: =AVERAGE(DataExp1.1!AD13:AD17) -> 0.040578674 | P16: =AVERAGE(DataExp1.1!AE13:AE17) -> 3.1331105
B17: 100 | L17: =AVERAGE(DataExp1.1!AF13:AF17) -> 4.0573849 | M17: =AVERAGE(DataExp1.1!AG13:AG17) -> 0.89865081 | N17: =AVERAGE(DataExp1.1!AH13:AH17) -> 75.918481 | O17: =AVERAGE(DataExp1.1!AI13:AI17) -> 0.040870485 | P17: =AVERAGE(DataExp1.1!AJ13:AJ17) -> 4.1135736
A18: EpiRAM | B18: 1 | L18: =AVERAGE(DataExp1.1!B22:B26) -> 4.5451398 | M18: =AVERAGE(DataExp1.1!C22:C26) -> 0.75511641 | N18: =AVERAGE(DataExp1.1!D22:D26) -> 0.044845013 | O18: =AVERAGE(DataExp1.1!E22:E26) -> 0.00013222936 | P18: =AVERAGE(DataExp1.1!F22:F26) -> 0.21877103
B19: 3 | L19: =AVERAGE(DataExp1.1!G22:G26) -> 5.0008254 | M19: =AVERAGE(DataExp1.1!H22:H26) -> 0.83545626 | N19: =AVERAGE(DataExp1.1!I22:I26) -> 0.047840026 | O19: =AVERAGE(DataExp1.1!J22:J26) -> 0.00013391411 | P19: =AVERAGE(DataExp1.1!K22:K26) -> 0.22898345
B20: 5 | L20: =AVERAGE(DataExp1.1!L22:L26) -> 5.1520558 | M20: =AVERAGE(DataExp1.1!M22:M26) -> 0.86004742 | N20: =AVERAGE(DataExp1.1!N22:N26) -> 0.047862539 | O20: =AVERAGE(DataExp1.1!O22:O26) -> 0.00013392026 | P20: =AVERAGE(DataExp1.1!P22:P26) -> 0.24615226
B21: 10 | L21: =AVERAGE(DataExp1.1!Q22:Q26) -> 5.063872 | M21: =AVERAGE(DataExp1.1!R22:R26) -> 0.84643463 | N21: =AVERAGE(DataExp1.1!S22:S26) -> 0.047856071 | O21: =AVERAGE(DataExp1.1!T22:T26) -> 0.00013392065 | P21: =AVERAGE(DataExp1.1!U22:U26) -> 0.28775277
B22: 20 | L22: =AVERAGE(DataExp1.1!V22:V26) -> 5.0919612 | M22: =AVERAGE(DataExp1.1!W22:W26) -> 0.85522739 | N22: =AVERAGE(DataExp1.1!X22:X26) -> 0.047852636 | O22: =AVERAGE(DataExp1.1!Y22:Y26) -> 0.00013391668 | P22: =AVERAGE(DataExp1.1!Z22:Z26) -> 0.31381936
B23: 50 | L23: =AVERAGE(DataExp1.1!AA22:AA26) -> 5.1348735 | M23: =AVERAGE(DataExp1.1!AB22:AB26) -> 0.85522739 | N23: =AVERAGE(DataExp1.1!AC22:AC26) -> 0.047862331 | O23: =AVERAGE(DataExp1.1!AD22:AD26) -> 0.00013391972 | P23: =AVERAGE(DataExp1.1!AE22:AE26) -> 0.5298604
B24: 100 | L24: =AVERAGE(DataExp1.1!AF22:AF26) -> 5.1012116 | M24: =AVERAGE(DataExp1.1!AG22:AG26) -> 0.85522739 | N24: =AVERAGE(DataExp1.1!AH22:AH26) -> 0.047848655 | O24: =AVERAGE(DataExp1.1!AI22:AI26) -> 0.00013391835 | P24: =AVERAGE(DataExp1.1!AJ22:AJ26) -> 0.83993425
A25: TaOx-HfOx | B25: 1 | L25: =AVERAGE(DataExp1.1!B31:B35) -> 69.119033 | M25: =AVERAGE(DataExp1.1!C31:C35) -> 9.1400505 | N25: =AVERAGE(DataExp1.1!D31:D35) -> 0.062164239 | O25: =AVERAGE(DataExp1.1!E31:E35) -> 1.8067908e-05 | P25: =AVERAGE(DataExp1.1!F31:F35) -> 2.0296194
B26: 3 | L26: =AVERAGE(DataExp1.1!G31:G35) -> 3.8112035 | M26: =AVERAGE(DataExp1.1!H31:H35) -> 0.69516314 | N26: =AVERAGE(DataExp1.1!I31:I35) -> 0.088190446 | O26: =AVERAGE(DataExp1.1!J31:J35) -> 2.7965649e-05 | P26: =AVERAGE(DataExp1.1!K31:K35) -> 2.2586493
B27: 5 | L27: =AVERAGE(DataExp1.1!L31:L35) -> 3.7940556 | M27: =AVERAGE(DataExp1.1!M31:M35) -> 0.70219775 | N27: =AVERAGE(DataExp1.1!N31:N35) -> 0.088326634 | O27: =AVERAGE(DataExp1.1!O31:O35) -> 2.8021685e-05 | P27: =AVERAGE(DataExp1.1!P31:P35) -> 2.2439172
B28: 10 | L28: =AVERAGE(DataExp1.1!Q31:Q35) -> 3.8227771 | M28: =AVERAGE(DataExp1.1!R31:R35) -> 0.71134643 | N28: =AVERAGE(DataExp1.1!S31:S35) -> 0.088408073 | O28: =AVERAGE(DataExp1.1!T31:T35) -> 2.8090593e-05 | P28: =AVERAGE(DataExp1.1!U31:U35) -> 2.3377426
B29: 20 | L29: =AVERAGE(DataExp1.1!V31:V35) -> 3.8203191 | M29: =AVERAGE(DataExp1.1!W31:W35) -> 0.70427532 | N29: =AVERAGE(DataExp1.1!X31:X35) -> 0.088381141 | O29: =AVERAGE(DataExp1.1!Y31:Y35) -> 2.8150047e-05 | P29: =AVERAGE(DataExp1.1!Z31:Z35) -> 2.504537
B30: 50 | L30: =AVERAGE(DataExp1.1!AA31:AA35) -> 3.7894569 | M30: =AVERAGE(DataExp1.1!AB31:AB35) -> 0.70514874 | N30: =AVERAGE(DataExp1.1!AC31:AC35) -> 0.088368656 | O30: =AVERAGE(DataExp1.1!AD31:AD35) -> 2.8378002e-05 | P30: =AVERAGE(DataExp1.1!AE31:AE35) -> 3.0570624
B31: 100 | L31: =AVERAGE(DataExp1.1!AF31:AF35) -> 3.927965 | M31: =AVERAGE(DataExp1.1!AG31:AG35) -> 0.71758144 | N31: =AVERAGE(DataExp1.1!AH31:AH35) -> 0.088513427 | O31: =AVERAGE(DataExp1.1!AI31:AI35) -> 2.8810038e-05 | P31: =AVERAGE(DataExp1.1!AJ31:AJ35) -> 4.0600382
A33: Ag-aSi | B33: 1 | C33: Ipertubed | D33: 128 | E33: 128 | F33: 1.12 | G33: 1 | H33: 1 | I33: 128 | J33: 128 | L33: =AVERAGE(DataExp1.1!B41:B45) -> 49.109114 | M33: =AVERAGE(DataExp1.1!C41:C45) -> 7.1307055 | N33: =AVERAGE(DataExp1.1!D41:D45) -> 273.03645 | O33: =AVERAGE(DataExp1.1!E41:E45) -> 0.00083304148 | P33: =AVERAGE(DataExp1.1!F41:F45) -> 1.8286528
B34: 3 | L34: =AVERAGE(DataExp1.1!G41:G45) -> 29.353773 | M34: =AVERAGE(DataExp1.1!H41:H45) -> 4.4551993 | N34: =AVERAGE(DataExp1.1!I41:I45) -> 449.88073 | O34: =AVERAGE(DataExp1.1!J41:J45) -> 0.0016180401 | P34: =AVERAGE(DataExp1.1!K41:K45) -> 1.9974823
B35: 5 | L35: =AVERAGE(DataExp1.1!L41:L45) -> 15.663363 | M35: =AVERAGE(DataExp1.1!M41:M45) -> 2.8870934 | N35: =AVERAGE(DataExp1.1!N41:N45) -> 533.09906 | O35: =AVERAGE(DataExp1.1!O41:O45) -> 0.001972683 | P35: =AVERAGE(DataExp1.1!P41:P45) -> 1.9856193
B36: 10 | L36: =AVERAGE(DataExp1.1!Q41:Q45) -> 2.6831689 | M36: =AVERAGE(DataExp1.1!R41:R45) -> 0.8595524 | N36: =AVERAGE(DataExp1.1!S41:S45) -> 616.52937 | O36: =AVERAGE(DataExp1.1!T41:T45) -> 0.0022415911 | P36: =AVERAGE(DataExp1.1!U41:U45) -> 2.0965623
B37: 20 | L37: =AVERAGE(DataExp1.1!V41:V45) -> 1.9767424 | M37: =AVERAGE(DataExp1.1!W41:W45) -> 0.49921019 | N37: =AVERAGE(DataExp1.1!X41:X45) -> 582.73242 | O37: =AVERAGE(DataExp1.1!Y41:Y45) -> 0.0021948611 | P37: =AVERAGE(DataExp1.1!Z41:Z45) -> #DIV/0!
B38: 50 | L38: =AVERAGE(DataExp1.1!AA41:AA45) -> 1.6365291 | M38: =AVERAGE(DataExp1.1!AB41:AB45) -> 0.5120584 | N38: =AVERAGE(DataExp1.1!AC41:AC45) -> 611.12481 | O38: =AVERAGE(DataExp1.1!AD41:AD45) -> 0.0022408296 | P38: =AVERAGE(DataExp1.1!AE41:AE45) -> #DIV/0!
B39: 100 | L39: =AVERAGE(DataExp1.1!AF41:AF45) -> 1.7066608 | M39: =AVERAGE(DataExp1.1!AG41:AG45) -> 0.41120745 | N39: =AVERAGE(DataExp1.1!AH41:AH45) -> 626.16801 | O39: =AVERAGE(DataExp1.1!AI41:AI45) -> 0.0023204803 | P39: =AVERAGE(DataExp1.1!AJ41:AJ45) -> #DIV/0!
A40: AlOx-HfO2 | B40: 1
B41: 3
B42: 5
...

Sheet DataExp1.2
B1: Ag-aSi (email-Eu-core-temporal)
B2: N=1 | E2: N=3 | H2: N = 5 | K2: N = 10 | N2: N = 20 | Q2: N = 50 | T2: N = 100
B3: L-2 Norm Error | C3: L-infty Norm Error | D3: Elapsed Time | E3: L-2 Norm Error | F3: L-infty Norm Error | G3: Elapsed Time | H3: L-2 Norm Error | I3: L-infty Norm Error | J3: Elapsed Time | K3: L-2 Norm Error | L3: L-infty Norm Error | M3: Elapsed Time | N3: L-2 Norm Error | O3: L-infty Norm Error | P3: Elapsed Time | Q3: L-2 Norm Error | R3: L-infty Norm Error | S3: Elapsed Time | T3: L-2 Norm Error | U3: L-infty Norm Error | V3: Elapsed Time
B4: 1422.6486 | C4: 45.929812 | D4: 11.247504 | E4: 705.57962 | F4: 23.691617 | G4: 11.541682 | H4: 445.21467 | I4: 15.637291 | J4: 11.768255 | K4: 13.397414 | L4: 2.8155393 | M4: 11.607558 | N4: 6.3181789 | O4: 2.0809505 | P4: 12.902581
B5: 1294.6106 | C5: 41.840665 | D5: 11.650308 | E5: 670.93315 | F5: 23.104075 | G5: 11.577505 | H5: 452.90528 | I5: 15.014382 | J5: 11.707543 | K5: 12.057505 | L5: 2.5488516 | M5: 12.105886 | N5: 8.6164837 | O5: 2.3923766 | P5: 12.541001
B6: 1289.0185 | C6: 41.622931 | D6: 11.790624 | E6: 671.16567 | F6: 23.600133 | G6: 11.659604 | H6: 382.52379 | I6: 14.509196 | J6: 11.677605 | K6: 7.5331515 | L6: 2.3080679 | M6: 11.790834 | N6: 9.3580004 | O6: 1.8491858 | P6: 12.672723
B7: 1296.2357 | C7: 41.876136 | D7: 11.498033 | E7: 708.34939 | F7: 24.184761 | G7: 11.661857 | H7: 447.07443 | I7: 15.606991 | J7: 11.606947 | K7: 9.4122965 | L7: 0.97370815 | M7: 11.75391 | N7: 6.6513362 | O7: 2.4394343 | P7: 12.763729
B8: 1289.0185 | C8: 41.622931 | D8: 11.680851 | E8: 11.661857 | F8: 23.650421 | G8: 11.6667 | H8: 442.05657 | I8: 15.161364 | J8: 11.557379 | K8: 11.790834 | L8: 2.0911467 | M8: 11.981241 | N8: 8.5318506 | O8: 2.2158731 | P8: 12.653918
B15: AlOx-HfO2 (email-Eu-core-temporal)
B16: N=1 | E16: N=3 | H16: N = 5 | K16: N = 10 | N16: N = 20 | Q16: N = 50 | T16: N = 100
B17: L-2 Norm Error | C17: L-infty Norm Error | D17: Elapsed Time | E17: L-2 Norm Error | F17: L-infty Norm Error | G17: Elapsed Time | H17: L-2 Norm Error | I17: L-infty Norm Error | J17: Elapsed Time | K17: L-2 Norm Error | L17: L-infty Norm Error | M17: Elapsed Time | N17: L-2 Norm Error | O17: L-infty Norm Error | P17: Elapsed Time | Q17: L-2 Norm Error | R17: L-infty Norm Error | S17: Elapsed Time | T17: L-2 Norm Error | U17: L-infty Norm Error | V17: Elapsed Time
B18: 3148.1656 | C18: 101.37085 | D18: 11.349321 | E18: 59.939719 | F18: 2.8714549 | G18: 11.42872 | H18: 10.325995 | I18: 1.5505351 | J18: 11.824993 | K18: 119.2563 | L18: 4.0501513 | M18: 11.631166 | N18: 109.05729 | O18: 4.2055401 | P18: 11.652021
B19: 3136.4726 | C19: 101.01306 | D19: 11.492187 | E19: 117.17192 | F19: 4.4313448 | G19: 11.43435 | H19: 53.787522 | I19: 2.5686537 | J19: 11.736213 | K19: 91.182858 | L19: 3.3550519 | M19: 11.735719
B20: 3223.9336 | C20: 103.78437 | D20: 11.414608 | E20: 59.934698 | F20: 2.8598087 | G20: 11.33347 | H20: 96.302103 | I20: 3.4612447 | J20: 11.66141 | K20: 97.975872 | L20: 3.4788745 | M20: 11.72212
B21: 3176.591 | C21: 102.3193 | D21: 11.390738 | E21: 90.807082 | F21: 3.3309464 | G21: 11.471031 | H21: 91.015108 | I21: 3.454855 | J21: 11.688694 | K21: 93.182364 | L21: 3.3661628 | M21: 11.750392
B22: 3205.8089 | C22: 103.23591 | D22: 11.275037 | E22: 50.576297 | F22: 2.2407281 | G22: 11.491829 | H22: 88.995976 | I22: 3.3984125 | J22: 11.668272 | K22: 98.761617 | L22: 3.5556758 | M22: 11.824485
H23: 112.84872 | I23: 4.2898189 | J23: 11.561189 | K23: 78.319908 | L23: 3.4998823 | M23: 11.871712
K24: 91.214005 | L24: 3.7516547 | M24: 11.709066
B29: EpiRAM (email-Eu-core-temporal)
B30: N=1 | E30: N=3 | H30: N = 5 | K30: N = 10 | N30: N = 20 | Q30: N = 50 | T30: N = 100
B31: L-2 Norm Error | C31: L-infty Norm Error | D31: Elapsed Time | E31: L-2 Norm Error | F31: L-infty Norm Error | G31: Elapsed Time | H31: L-2 Norm Error | I31: L-infty Norm Error | J31: Elapsed Time | K31: L-2 Norm Error | L31: L-infty Norm Error | M31: Elapsed Time | N31: L-2 Norm Error | O31: L-infty Norm Error | P31: Elapsed Time | Q31: L-2 Norm Error | R31: L-infty Norm Error | S31: Elapsed Time | T31: L-2 Norm Error | U31: L-infty Norm Error | V31: Elapsed Time
B32: 345.21337 | C32: 11.156075 | D32: 11.377435 | E32: 38.513263 | F32: 1.6304686 | G32: 11.498995 | H32: 38.875083 | I32: 1.6722659 | J32: 11.604146 | K32: 36.945375 | L32: 1.547854 | M32: 11.725799
B33: 345.14754 | C33: 11.256697 | D33: 11.487327 | E33: 39.154639 | F33: 1.6396369 | G33: 11.616765 | H33: 36.967246 | I33: 1.5516607 | J33: 11.741249 | K33: 37.639439 | L33: 1.5486967 | M33: 11.662418
B34: 345.21337 | C34: 11.156075 | D34: 11.363629 | E34: 38.934355 | F34: 1.6385337 | G34: 11.685825 | H34: 38.916234 | I34: 1.6642312 | J34: 11.189519 | K34: 36.841169 | L34: 1.5521356 | M34: 11.729651
B35: 345.21337 | C35: 11.156075 | D35: 11.343361 | E35: 38.91884 | F35: 1.6604857 | G35: 11.519902 | H35: 38.622679 | I35: 1.593895 | J35: 11.554682 | K35: 38.984239 | L35: 1.5491105 | M35: 11.653014
B36: 345.14754 | C36: 11.256697 | D36: 11.36064 | E36: 39.087176 | F36: 1.5583171 | G36: 11.5858 | H36: 39.015267 | I36: 1.6742727 | J36: 11.673377 | K36: 38.893644 | L36: 1.6642312 | M36: 11.713455
H37: 37.766138 | I37: 1.5500754 | J37: 11.636682
H38: 38.916234 | I38: 1.6642312 | J38: 11.735893
B43: TaOx-HfOx (email-Eu-core-temporal)
B44: N=1 | E44: N=3 | H44: N = 5 | K44: N = 10 | N44: N = 20 | Q44: N = 50 | T44: N = 100
B45: L-2 Norm Error | C45: L-infty Norm Error | D45: Elapsed Time | E45: L-2 Norm Error | F45: L-infty Norm Error | G45: Elapsed Time | H45: L-2 Norm Error | I45: L-infty Norm Error | J45: Elapsed Time | K45: L-2 Norm Error | L45: L-infty Norm Error | M45: Elapsed Time | N45: L-2 Norm Error | O45: L-infty Norm Error | P45: Elapsed Time | Q45: L-2 Norm Error | R45: L-infty Norm Error | S45: Elapsed Time | T45: L-2 Norm Error | U45: L-infty Norm Error | V45: Elapsed Time
B46: 1261.443 | C46: 41.440516 | D46: 11.526838 | E46: 45.443277 | F46: 2.8643923 | G46: 11.506747 | K46: 93.089756 | L46: 3.3021945 | M46: 11.680633
B47: 1258.9472 | C47: 41.457192 | D47: 11.374178 | E47: 40.326314 | F47: 2.8997169 | G47: 11.515214
B48: 1272.841 | C48: 41.667284 | D48: 11.502956 | E48: 36.314017 | F48: 2.7153858 | G48: 11.661874
B49: 1262.3253 | C49: 41.564493 | D49: 11.484598 | E49: 45.442736 | F49: 2.8642774 | G49: 11.473039
B50: 1257.6915 | C50: 41.435255 | D50: 11.409185 | E50: 40.324953 | F50: 2.8998395 | G50: 11.663552

Sheet Experiment 1.2
A1: Decentralized Computation (Large-scale); Fixed Number of Iterations for Error Correction; Aplied Error Correction to all devices Run 10 replications for each number of iterations
A3: Material | B3: No. iteration | C3: Matrix Name | D3: Matrix Row | E3: Matrix Column | F3: Conditioning Number | G3: MCA Rows | H3: MCA Columns | I3: Cell Rows | J3: Cell Columns | K3: L-2 Norm Error (Mean) | L3: L-infty Norm Error (Mean) | M3: Acc. Write Latency (Mean) | N3: Acc. Write Energy (Mean) | O3: Elapsed Time for VMM
A4: Ag-aSi | B4: 1 | C4: email-Eu-core-temporal | D4: 1005 | E4: 1005 | G4: 8 | H4: 8 | I4: 128 | J4: 128 | K4: =AVERAGE(DataExp1.2!B4:B13) -> 1318.3064 | L4: =AVERAGE(DataExp1.2!C4:C13) -> 42.578495 | M4: 1031.6912 | N4: 0.010704642
B5: 3 | K5: =AVERAGE(DataExp1.2!E4:E13) -> 553.53794 | L5: =AVERAGE(DataExp1.2!F4:F13) -> 23.646201 | M5: 2037.9508 | N5: 0.020295989
B6: 5 | K6: =AVERAGE(DataExp1.2!H4:H13) -> 433.95495 | L6: =AVERAGE(DataExp1.2!I4:I13) -> 15.185845 | M6: 2541.3986 | N6: 0.024744345
B7: 10 | K7: =AVERAGE(DataExp1.2!K4:K13) -> 10.83824 | L7: =AVERAGE(DataExp1.2!L4:L13) -> 2.1474627 | M7: 2261.5468 | N7: 0.021991732
B8: 20 | K8: =AVERAGE(DataExp1.2!N4:N13) -> 7.8951699 | L8: =AVERAGE(DataExp1.2!O4:O13) -> 2.1955641 | M8: 2901.5632 | N8: 0.027777793
B9: 50
B10: 100
A11: AlOx-HfO2 | B11: 1 | K11: =AVERAGE(DataExp1.2!B18:B27) -> 3178.1943 | L11: =AVERAGE(DataExp1.2!C18:C27) -> 102.3447 | M11: 142.35263 | N11: 0.15901866
B12: 3 | K12: =AVERAGE(DataExp1.2!E18:E27) -> 75.685942 | L12: =AVERAGE(DataExp1.2!F18:F27) -> 3.1468566 | M12: 469.98055 | N12: 0.56156656
B13: 5 | K13: =AVERAGE(DataExp1.2!H18:H27) -> 75.545905 | L13: =AVERAGE(DataExp1.2!I18:I27) -> 3.1205867 | M13: 477.62379 | N13: 0.57532112
B14: 10 | K14: =AVERAGE(DataExp1.2!K18:K27) -> 95.698989 | L14: =AVERAGE(DataExp1.2!L18:L27) -> 3.5796362 | M14: 480.72598 | N14: 0.57873323
B15: 20 | M15: 479.0193 | N15: 0.57817839
B16: 50
B17: 100
A18: EpiRAM | B18: 1 | K18: =AVERAGE(DataExp1.2!B32:B41) -> 345.18704 | L18: =AVERAGE(DataExp1.2!C32:C41) -> 11.196324 | M18: 45.632296 | N18: 0.38384376
B19: 3 | K19: =AVERAGE(DataExp1.2!E32:E41) -> 38.921654 | L19: =AVERAGE(DataExp1.2!F32:F41) -> 1.6254884 | M19: 54.454427 | N19: 0.42563633
B20: 5
B21: 10
B22: 20
B23: 50
B24: 100
A25: TaOx-HfOx | B25: 1 | M25: 0.22804703 | N25: 0.00016157759
B26: 3 | M26: 0.41259237 | N26: 0.00029273051
B27: 5
B28: 10
B29: 20
B30: 50
B31: 100

Sheet DataExp2
B1: Ag-aSi (bcsstk02) | R1: AlOx-HfO2 (bcsstk02) | AI1: EpiRAM (bcsstk02) | AY1: TaOx-HfOx
B2: N=1 | E2: N=3 | H2: N = 5 | K2: N = 10 | N2: N = 1000 | R2: N=1 | U2: N=3 | X2: N = 5 | AA2: N = 10 | AD2: N = 1000 | AI2: N=1 | AL2: N=3 | AO2: N = 5 | AR2: N = 10 | AU2: N = 1000 | AY2: N=1 | BB2: N=3 | BE2: N = 5 | BH2: N = 10 | BK2: N = 1000
B3: L-2 Norm Error | C3: L-infty Norm Error | D3: Elapsed Time | E3: L-2 Norm Error | F3: L-infty Norm Error | G3: Elapsed Time | H3: L-2 Norm Error | I3: L-infty Norm Error | J3: Elapsed Time | K3: L-2 Norm Error | L3: L-infty Norm Error | M3: Elapsed Time | N3: L-2 Norm Error | O3: L-infty Norm Error | P3: Elapsed Time | R3: L-2 Norm Error | S3: L-infty Norm Error | T3: Elapsed Time | U3: L-2 Norm Error | V3: L-infty Norm Error | W3: Elapsed Time | X3: L-2 Norm Error | Y3: L-infty Norm Error | Z3: Elapsed Time | AA3: L-2 Norm Error | AB3: L-infty Norm Error | AC3: Elapsed Time | AD3: L-2 Norm Error | AE3: L-infty Norm Error | AF3: Elapsed Time | AI3: L-2 Norm Error | AJ3: L-infty Norm Error | AK3: Elapsed Time | AL3: L-2 Norm Error | AM3: L-infty Norm Error | AN3: Elapsed Time | AO3: L-2 Norm Error | AP3: L-infty Norm Error | AQ3: Elapsed Time | AR3: L-2 Norm Error | AS3: L-infty Norm Error | AT3: Elapsed Time | AU3: L-2 Norm Error | AV3: L-infty Norm Error | AW3: Elapsed Time | AY3: L-2 Norm Error | AZ3: L-infty Norm Error | BA3: Elapsed Time | BB3: L-2 Norm Error | BC3: L-infty Norm Error | BD3: Elapsed Time | BE3: L-2 Norm Error | BF3: L-infty Norm Error | BG3: Elapsed Time | BH3: L-2 Norm Error | BI3: L-infty Norm Error | BJ3: Elapsed Time | BK3: L-2 Norm Error | BL3: L-infty Norm Error | BM3: Elapsed Time
B4: 12.368384 | C4: 1.8726505 | D4: 0.22172141 | E4: 6.9113127 | F4: 1.1748781 | G4: 0.22073436 | H4: 3.3026619 | I4: 0.73814624 | J4: 0.15456867 | K4: 3.1930044 | L4: 0.7309676 | M4: 0.16689682 | N4: 3.0780635 | O4: 0.7310308 | P4: 0.20253992 | R4: 25.211133 | S4: 3.5527606 | T4: 0.20949483 | U4: 0.93318564 | V4: 0.29765195 | W4: 0.15252137 | X4: 2.7568276 | Y4: 0.61912335 | Z4: 0.15566039 | AA4: 1.0901443 | AB4: 0.45349746 | AC4: 0.16643858 | AD4: 3.5110351 | AE4: 0.73729848 | AF4: 0.17016816 | AI4: 2.028202 | AJ4: 0.37754673 | AK4: 0.15384221 | AL4: 2.9331435 | AM4: 0.65213375 | AN4: 0.16463685 | AO4: 3.1835707 | AP4: 0.6556513 | AQ4: 0.17476344 | AR4: 3.044606 | AS4: 0.65226013 | AT4: 0.16964746 | AU4: 3.0228865 | AV4: 0.65213375 | AW4: 0.15408826 | AY4: 23.193891 | AZ4: 3.2327059 | BA4: 0.19454718 | BB4: 2.7808855 | BC4: 0.61912335 | BD4: 0.1992712 | BE4: 2.8682988 | BF4: 0.65160317 | BG4: 0.1508944 | BH4: 2.8157658 | BI4: 0.61912335 | BJ4: 0.1571815 | BK4: 2.8157658 | BL4: 0.61912335 | BM4: 0.15600681
B5: 13.241512 | C5: 2.0159331 | D5: 0.19146562 | E5: 6.3271323 | F5: 1.1748781 | G5: 0.17127657 | H5: 3.1133275 | I5: 0.77858803 | J5: 0.15554929 | K5: 2.2473292 | L5: 0.52590186 | M5: 0.16840792 | N5: 2.1979186 | O5: 0.52590186 | P5: 0.16590714 | R5: 24.9806 | S5: 3.5527606 | T5: 0.19001079 | U5: 1.5684956 | V5: 0.49800334 | W5: 0.14881277 | X5: 2.700022 | Y5: 0.61909176 | Z5: 0.15234447 | AA5: 3.3726483 | AB5: 0.73833322 | AC5: 0.16285777 | AD5: 3.7353311 | AE5: 0.74867532 | AF5: 0.16232038 | AI5: 2.0576101 | AJ5: 0.37754673 | AK5: 0.14367342 | AL5: 3.0231718 | AM5: 0.65213375 | AN5: 0.15351915 | AO5: 3.0014743 | AP5: 0.65213375 | AQ5: 0.18802881 | AR5: 3.0732722 | AS5: 0.65213375 | AT5: 0.16455007 | AU5: 3.083691 | AV5: 0.65226013 | AW5: 0.15624857 | AY5: 23.194889 | AZ5: 3.2327059 | BA5: 0.21980357 | BB5: 2.7808855 | BC5: 0.61912335 | BD5: 0.1990447 | BE5: 2.762184 | BF5: 0.61912335 | BG5: 0.15681314 | BH5: 2.700022 | BI5: 0.61909176 | BJ5: 0.15541315 | BK5: 2.4319526 | BL5: 0.61909176 | BM5: 0.15285587
B6: 12.72955 | C6: 1.8726505 | D6: 0.1908474 | E6: 6.9113127 | F6: 1.1748781 | G6: 0.22210121 | H6: 2.7346711 | I6: 0.71530431 | J6: 0.15457416 | K6: 2.3857349 | L6: 0.52590186 | M6: 0.16672039 | N6: 2.5588729 | O6: 0.54516516 | P6: 0.16805696 | R6: 25.877778 | S6: 3.6278386 | T6: 0.21006799 | U6: 1.21981 | V6: 0.47616456 | W6: 0.15312433 | X6: 2.8157658 | Y6: 0.61912335 | Z6: 0.15786219 | AA6: 3.4934559 | AB6: 0.74538684 | AC6: 0.16499352 | AD6: 0.91339994 | AE6: 0.29765195 | AF6: 0.16355205 | AI6: 2.0124832 | AJ6: 0.37754673 | AK6: 0.15831113 | AL6: 3.1835707 | AM6: 0.6556513 | AN6: 0.15638685 | AO6: 3.0052609 | AP6: 0.65213375 | AQ6: 0.17257547 | AR6: 2.9332439 | AS6: 0.65213375 | AT6: 0.17924476 | AU6: 3.140553 | AV6: 0.65226013 | AW6: 0.1519351 | AY6: 23.193891 | AZ6: 3.2327059 | BA6: 0.1983285 | BB6: 2.7246394 | BC6: 0.61909176 | BD6: 0.19775939 | BE6: 2.700022 | BF6: 0.61909176 | BG6: 0.1545701 | BH6: 2.504036 | BI6: 0.61909176 | BJ6: 0.15583968 | BK6: 2.6282613 | BL6: 0.61909176 | BM6: 0.1526103
B7: 12.538987 | C7: 1.8726505 | D7: 0.19119835 | E7: 6.7915255 | F7: 1.239585 | G7: 0.21939301 | H7: 2.4162428 | I7: 0.65583692 | J7: 0.1556406 | K7: 2.347521 | L7: 0.52590186 | M7: 0.16694856 | N7: 2.1116839 | O7: 0.51982769 | P7: 0.17736864 | R7: 25.517916 | S7: 3.5880447 | T7: 0.18972802 | U7: 1.2486288 | V7: 0.47616456 | W7: 0.1512208 | X7: 2.700022 | Y7: 0.61909176 | Z7: 0.15396738 | AA7: 0.91566664 | AB7: 0.31433419 | AC7: 0.16472459 | AD7: 3.736242 | AE7: 0.74867532 | AF7: 0.16232395 | AI7: 1.9873313 | AJ7: 0.37754673 | AK7: 0.15082407 | AL7: 2.9709095 | AM7: 0.65213375 | AN7: 0.1566329 | AO7: 3.1234714 | AP7: 0.65226013 | AQ7: 0.16536331 | AR7: 2.9332439 | AS7: 0.65213375 | AT7: 0.16520929 | AU7: 3.140553 | AV7: 0.65226013 | AW7: 0.1519351 | AY7: 23.149823 | AZ7: 3.2327059 | BA7: 0.19557405 | BB7: 2.8033491 | BC7: 0.61912335 | BD7: 0.19774628 | BE7: 2.8275177 | BF7: 0.61924973 | BG7: 0.15472627 | BH7: 2.6282613 | BI7: 0.61909176 | BJ7: 0.14970541 | BK7: 2.8157658 | BL7: 0.61912335 | BM7: 0.15581179
B8: 13.397439 | C8: 2.0648503 | D8: 0.1897788 | E8: 6.6953422 | F8: 1.239585 | G8: 0.22022748 | H8: 2.8119871 | I8: 0.72171676 | J8: 0.16279078 | K8: 2.4492995 | L8: 0.52602824 | M8: 0.16912389 | N8: 3.158576 | O8: 0.7309676 | P8: 0.17199111 | R8: 24.02708 | S8: 3.40387 | T8: 0.19209957 | U8: 1.0193237 | V8: 0.43914552 | W8: 0.15029311 | X8: 2.7266173 | Y8: 0.61909176 | Z8: 0.15960121 | AA8: 3.0801789 | AB8: 0.60759644 | AC8: 0.16113353 | AD8: 3.6940441 | AE8: 0.74867532 | AF8: 0.16350698 | AI8: 2.0045867 | AJ8: 0.37754673 | AK8: 0.14465332 | AL8: 2.8887491 | AM8: 0.65213375 | AN8: 0.16466808 | AO8: 3.1300088 | AP8: 0.65226013 | AQ8: 0.20038581 | AR8: 3.0895273 | AS8: 0.65226013 | AT8: 0.16087198 | AU8: 3.1234714 | AV8: 0.65226013 | AW8: 0.15936399 | AY8: 23.154218 | AZ8: 3.2327059 | BA8: 0.15848541 | BB8: 2.7808855 | BC8: 0.61912335 | BD8: 0.19962668 | BE8: 2.7266173 | BF8: 0.61909176 | BG8: 0.1547358 | BH8: 2.6282613 | BI8: 0.61909176 | BJ8: 0.15323472 | BK8: 2.7916221 | BL8: 0.61912335 | BM8: 0.15216517

Sheet Experiment 2
D1: Centralized Computation; Fixed Number of Iterations for Error Correction; No Error Correction Run 5 replications for each number of iterations
A3: Material | B3: No. iteration | C3: Matrix Name | D3: Matrix Row | E3: Matrix Column | F3: Conditioning Number | G3: MCA Rows | H3: MCA Columns | I3: Cell Rows | J3: Cell Columns | K3: L-2 Norm Error (Mean) | L3: L-infty Norm Error (Mean) | M3: Elapsed Time for VMM
A4: Ag-aSi | B4: 1 | C4: bcsstk02 | D4: 66 | E4: 66 | G4: 1 | H4: 1 | I4: 66 | J4: 66 | K4: =AVERAGE(DataExp2!B4:B8) -> 12.855174 | L4: =AVERAGE(DataExp2!C4:C8) -> 1.939747 | M4: =AVERAGE(DataExp2!D4:D8) -> 0.19700232
B5: 3 | K5: =AVERAGE(DataExp2!E4:E8) -> 6.7273251 | L5: =AVERAGE(DataExp2!F4:F8) -> 1.2007609 | M5: =AVERAGE(DataExp2!G4:G8) -> 0.21074653
B6: 5 | K6: =AVERAGE(DataExp2!H4:H8) -> 2.8757781 | L6: =AVERAGE(DataExp2!I4:I8) -> 0.72191845 | M6: =AVERAGE(DataExp2!J4:J8) -> 0.1566247
B7: 10 | K7: =AVERAGE(DataExp2!K4:K8) -> 2.5245778 | L7: =AVERAGE(DataExp2!L4:L8) -> 0.56694029 | M7: =AVERAGE(DataExp2!M4:M8) -> 0.16761951
B8: 1000 | K8: =AVERAGE(DataExp2!N4:N8) -> 2.621023 | L8: =AVERAGE(DataExp2!O4:O8) -> 0.61057862 | M8: =AVERAGE(DataExp2!P4:P8) -> 0.17717276
A9: AlOx-HfO2 | B9: 1 | K9: =AVERAGE(DataExp2!R4:R8) -> 25.122901 | L9: =AVERAGE(DataExp2!S4:S8) -> 3.5450549 | M9: =AVERAGE(DataExp2!T4:T8) -> 0.19828024
B10: 3 | K10: =AVERAGE(DataExp2!U4:U8) -> 1.1978888 | L10: =AVERAGE(DataExp2!V4:V8) -> 0.43742599 | M10: =AVERAGE(DataExp2!W4:W8) -> 0.15119448
B11: 5 | K11: =AVERAGE(DataExp2!X4:X8) -> 2.7398509 | L11: =AVERAGE(DataExp2!Y4:Y8) -> 0.6191044 | M11: =AVERAGE(DataExp2!Z4:Z8) -> 0.15588713
B12: 10 | K12: =AVERAGE(DataExp2!AA4:AA8) -> 2.3904188 | L12: =AVERAGE(DataExp2!AB4:AB8) -> 0.57182963 | M12: =AVERAGE(DataExp2!AC4:AC8) -> 0.1640296
B13: 1000 | K13: =AVERAGE(DataExp2!AD4:AD8) -> 3.1180104 | L13: =AVERAGE(DataExp2!AE4:AE8) -> 0.65619528 | M13: =AVERAGE(DataExp2!AF4:AF8) -> 0.1643743
A14: EpiRAM | B14: 1 | K14: =AVERAGE(DataExp2!AI4:AI8) -> 2.0180427 | L14: =AVERAGE(DataExp2!AJ4:AJ8) -> 0.37754673 | M14: =AVERAGE(DataExp2!AK4:AK8) -> 0.15026083
B15: 3 | K15: =AVERAGE(DataExp2!AL4:AL8) -> 2.9999089 | L15: =AVERAGE(DataExp2!AM4:AM8) -> 0.65283726 | M15: =AVERAGE(DataExp2!AN4:AN8) -> 0.15916877
B16: 5 | K16: =AVERAGE(DataExp2!AO4:AO8) -> 3.0887572 | L16: =AVERAGE(DataExp2!AP4:AP8) -> 0.65288781 | M16: =AVERAGE(DataExp2!AQ4:AQ8) -> 0.18022337
B17: 10 | K17: =AVERAGE(DataExp2!AR4:AR8) -> 3.0147786 | L17: =AVERAGE(DataExp2!AS4:AS8) -> 0.65218431 | M17: =AVERAGE(DataExp2!AT4:AT8) -> 0.16790471
B18: 1000 | K18: =AVERAGE(DataExp2!AU4:AU8) -> 3.102231 | L18: =AVERAGE(DataExp2!AV4:AV8) -> 0.65223486 | M18: =AVERAGE(DataExp2!AW4:AW8) -> 0.1547142
A19: TaOx-HfOx | B19: 1 | K19: =AVERAGE(DataExp2!AY4:AY8) -> 23.177343 | L19: =AVERAGE(DataExp2!AZ4:AZ8) -> 3.2327059 | M19: =AVERAGE(DataExp2!BA4:BA8) -> 0.19334774
B20: 3 | K20: =AVERAGE(DataExp2!BB4:BB8) -> 2.774129 | L20: =AVERAGE(DataExp2!BC4:BC8) -> 0.61911703 | M20: =AVERAGE(DataExp2!BD4:BD8) -> 0.19868965
B21: 5 | K21: =AVERAGE(DataExp2!BE4:BE8) -> 2.776928 | L21: =AVERAGE(DataExp2!BF4:BF8) -> 0.62563195 | M21: =AVERAGE(DataExp2!BG4:BG8) -> 0.15434794
B22: 10 | K22: =AVERAGE(DataExp2!BH4:BH8) -> 2.6552693 | L22: =AVERAGE(DataExp2!BI4:BI8) -> 0.61909808 | M22: =AVERAGE(DataExp2!BJ4:BJ8) -> 0.15427489
B23: 1000 | K23: =AVERAGE(DataExp2!BK4:BK8) -> 2.6966735 | L23: =AVERAGE(DataExp2!BL4:BL8) -> 0.61911072 | M23: =AVERAGE(DataExp2!BM4:BM8) -> 0.15388999

Sheet Experiment 3
A2: Material | B2: No. iteration | C2: Matrix Name | D2: Matrix Row | E2: Matrix Column | F2: Conditioning Number | G2: MCA Rows | H2: MCA Columns | I2: Cell Rows | J2: Cell Columns | K2: L-2 Norm Error (Mean) | L2: L-infty Norm Error (Mean)
A3: Ag-aSi | B3: 1 | C3: bcsstk02 | D3: 66 | E3: 66 | G3: 1 | H3: 1 | I3: 66 | J3: 66 | K3: 24.272211 | L3: 3.3054398
B4: 3 | K4: 10.596633 | L4: 1.5955636
B5: 5 | K5: 4.5624707 | L5: 0.80189414
B6: 10 | K6: 0.61017152 | L6: 0.1881751
B7: 100 | K7: 0.56361849 | L7: 0.19728247
A8: AlOx-HfO2 | B8: 1 | K8: 51.370886 | L8: 6.6885951
B9: 3 | K9: 2.1067017 | L9: 0.40789972
B10: 5 | K10: 2.8064566 | L10: 0.67455402
B11: 10 | K11: 1.8870454 | L11: 0.37616173
B12: 100 | K12: 1.6795645 | L12: 0.41984578
A13: EpiRAM | B13: 1 | K13: 1.9779697 | L13: 0.37754673
B14: 3 | K14: 3.1862607 | L14: 0.6556513
B15: 5 | K15: 3.1662124 | L15: 0.65226013
B16: 10 | K16: 3.0769912 | L16: 0.65226013
B17: 100 | K17: 3.1294599 | L17: 0.65226013
A18: TaOx-HfOx | B18: 1 | K18: 34.454845 | L18: 4.5813182
B19: 3 | K19: 1.9521931 | L19: 0.33857361
B20: 5 | K20: 2.004344 | L20: 0.34338396
B21: 10 | K21: 2.0041611 | L21: 2.0041611
B22: 100 | K22: 2.0126024 | L22: 0.34214779

Sheet DataExp4
B1: Ag-aSi (bcsstk02) | R1: AlOx-HfO2 (bcsstk02) | AE1: EpiRAM (bcsstk02) | AR1: TaOx-HfOx
B2: N=1 | E2: N=3 | H2: N = 5 | K2: N = 10 | N2: N = 100 | R2: N=1 | U2: N=3 | X2: N = 5 | AA2: N = 10 | AE2: N=1 | AH2: N=3 | AK2: N = 5 | AN2: N = 10 | AR2: N=1 | AU2: N=3 | AX2: N = 5 | BA2: N = 10
B3: L-2 Norm Error | C3: L-infty Norm Error | D3: Elapsed Time | E3: L-2 Norm Error | F3: L-infty Norm Error | G3: Elapsed Time | H3: L-2 Norm Error | I3: L-infty Norm Error | J3: Elapsed Time | K3: L-2 Norm Error | L3: L-infty Norm Error | M3: Elapsed Time | N3: L-2 Norm Error | O3: L-infty Norm Error | P3: Elapsed Time | R3: L-2 Norm Error | S3: L-infty Norm Error | T3: Elapsed Time | U3: L-2 Norm Error | V3: L-infty Norm Error | W3: Elapsed Time | X3: L-2 Norm Error | Y3: L-infty Norm Error | Z3: Elapsed Time | AA3: L-2 Norm Error | AB3: L-infty Norm Error | AC3: Elapsed Time | AE3: L-2 Norm Error | AF3: L-infty Norm Error | AG3: Elapsed Time | AH3: L-2 Norm Error | AI3: L-infty Norm Error | AJ3: Elapsed Time | AK3: L-2 Norm Error | AL3: L-infty Norm Error | AM3: Elapsed Time | AN3: L-2 Norm Error | AO3: L-infty Norm Error | AP3: Elapsed Time | AR3: L-2 Norm Error | AS3: L-infty Norm Error | AT3: Elapsed Time | AU3: L-2 Norm Error | AV3: L-infty Norm Error | AW3: Elapsed Time | AX3: L-2 Norm Error | AY3: L-infty Norm Error | AZ3: Elapsed Time | BA3: L-2 Norm Error | BB3: L-infty Norm Error | BC3: Elapsed Time
